<!DOCTYPE html>
<html lang="en">
<head>
    <meta charset="UTF-8">
    <meta name="viewport" content="width=device-width, initial-scale=1.0">
    <title>Document</title>
</head>
<body>
    <script>
    //let mypromise = new Promise((resolve, reject) => {
        //let success = true;
        //if(success) {
            //resolve("The operation was successful");
        //} else {
            //reject("The operation failed");
        //}
    //});

    //mypromise
    //.then(result => {
        //console.log(result);
    //})
    //.catch(error => {
        //console.log(error);
    //});

    //chaining promise:
    //let promise=new Promise((resolve,reject)=>{
        //resolve(5);  //initial resolve value is 5
    //})
    //promise
    //.then(result=>{
        //console.log(result);
        //return result*2;
    //})
    //.then(result=>{
        //console.log(result);
        //return result+3  //return a new value
    //})
    //.then(result=>{
        //console.log(result);
    //})
    //.catch(error=>{
        //console.log("error",error);
    //})

    let pro=new Promise((resolve,reject)=>{
        resolve(5);
    })
    pro.then(result=>{
        console.log(result)
        setTimeout((pro)=>{
            console.log("success")
        },3000)
    })
    </script>
</body>
</html>


Theory notes :
Promise:
	• A promise is a special JavaScript object that represents the eventual completion(or failure) of an asynchronous operation.
	• It allows to handle asynchronous tasks more efficiently than callbacks.
Three states :
1.pending : The initial state , the promise is still waiting for the operation to finish.
2.fulfilled: The operation completed successfully.
3.rejected: The operation failed;

Exp:
1.To Create a promise - new promise()
Two parameters-
Resolve -- to mark the promise as successfully.
Reject -- mark it as failed

2.handling the result :
.then() method is called when promise is fulfilled.
It will receives the result from resolve()
.catch() method is called if the promise is rejected it receives the error message from reject()

Chaining promises:
Ex:

let promise=new Promise((resolve,reject)=>{
    resolve(5);  //initial resolve value is 5
})
promise
.then(result=>{
    console.log(result);
    return result*2;
})
.then(result=>{
    console.log(result);
    return result+3  //return a new value
})
.then(result=>{
    console.log(result);
})
.catch(error=>{
    console.log("error",error);
})

Ex: promise with setTimeout
--asynchronous task using settimeout, and the promise will resolve after a certain amount of time


let pro=new Promise((resolve,reject)=>{
        resolve(5);
    })
    pro.then(result=>{
        console.log(result)
        setTimeout((pro)=>{
            console.log("success")
        },3000)
    })

